<?xml version="1.0" encoding="UTF-8"?>
<robot name="yam_color">
  <joint name="joint1" type="revolute">
    <origin xyz="0. 0. 0.0631" rpy="1.5707964 -1.5707964 0. "/>
    <parent link="base_link"/>
    <child link="link_1"/>
    <axis xyz="1. 0. 0."/>
    <limit lower="-2.61799" upper="3.13" effort="10" velocity="10"/>
  </joint>
  <joint name="joint2" type="revolute">
    <origin xyz="0.0409 -0.02 -0.000025" rpy="1.5707964 1.5707963 0. "/>
    <parent link="link_1"/>
    <child link="link_2"/>
    <axis xyz="1. 0. 0."/>
    <limit lower="0." upper="3.65" effort="10" velocity="10"/>
  </joint>
  <joint name="joint3" type="revolute">
    <origin xyz="0. 0. -0.264" rpy="0. 0. 3.1415927"/>
    <parent link="link_2"/>
    <child link="link_3"/>
    <axis xyz="1. 0. 0."/>
    <limit lower="0." upper="3.13" effort="10" velocity="10"/>
  </joint>
  <joint name="joint4" type="revolute">
    <origin xyz="0. -0.06 0.245" rpy="0. 0. 0."/>
    <parent link="link_3"/>
    <child link="link_4"/>
    <axis xyz="1. 0. 0."/>
    <limit lower="-1.5708" upper="1.5708" effort="10." velocity="10"/>
  </joint>
  <joint name="joint5" type="revolute">
    <origin xyz="0.000025 -0.0395 0.074 " rpy="1.5707964 0. 1.5707964"/>
    <parent link="link_4"/>
    <child link="link_5"/>
    <axis xyz="1. 0. 0."/>
    <limit lower="-1.5708" upper="1.5708" effort="10." velocity="10"/>
  </joint>
  <joint name="joint6" type="revolute">
    <origin xyz="0.0395 0.0353 0. " rpy="0. 0. 1.5707964"/>
    <parent link="link_5"/>
    <child link="link_6"/>
    <axis xyz="1. 0. 0."/>
    <limit lower="-2.0944" upper="2.0944" effort="10." velocity="10"/>
  </joint>

  <joint name="gripper" type="prismatic">
    <origin xyz="0.0605 0.0392 0.037 " rpy="0. 1.5707963 0. "/>
    <parent link="link_6"/>
    <child link="link_left_finger"/>
    <axis xyz="1. 0. 0."/>
    <limit lower="0.006" upper="0.055" effort="100" velocity="1."/>
  </joint>
  <joint name="gripper_mirror" type="prismatic">
    <origin xyz="0.0605 -0.0392 -0.037 " rpy="0. 1.5707963 0. "/>
    <parent link="link_6"/>
    <child link="link_right_finger"/>
    <axis xyz="1. 0. 0."/>
    <limit lower="0.006" upper="0.055" effort="100." velocity="1"/>
    <mimic joint="gripper" multiplier="-1" offset="0"/>
  </joint>

  <link name="link_1">
    <inertial>
      <origin xyz="-0.00192861 -0.00795735 0.0208176" rpy="0. 0. 0."/>
      <mass value="0.12415"/>
      <inertia ixx="5.98038e-05" ixy="-4.5902e-06" ixz="7.411e-06" iyy="0.000169215" iyz="1.68342e-05" izz="0.000156182"/>
    </inertial>
    <visual>
      <origin xyz="-0.0632 0.0000002 -0.0000005" rpy="0. 1.5707963 0. "/>
      <geometry>
        <mesh filename="assets_2/link_1_visuals_model2__2_model2__2.obj" scale="1. 1. 1."/>

      </geometry>
    </visual>
  </link>
  <link name="link_2">
    <inertial>
      <origin xyz="0.132008 2.10599e-06 0.000293073" rpy="0. 0. 0."/>
      <mass value="1.24434"/>
      <inertia ixx="0.000683304" ixy="1.99503e-09" ixz="3.68337e-09" iyy="0.0121902" iyz="3.20067e-09" izz="0.0121318"/>
    </inertial>
    <visual>
      <origin xyz="-0.0000245 -0.1041 -0.0199992" rpy="-1.5707964 -0. 0. "/>
      <geometry>
        <mesh filename="assets_2/link_2_visuals_model2__3_model2__3.obj" scale="1. 1. 1."/>
      </geometry>
    </visual>
    <visual>
      <origin xyz="-0.0000245 -0.1041 -0.0199992" rpy="-1.5707964 -0. 0. "/>
      <geometry>
        <mesh filename="assets_2/link_2_visuals_model2__4_model2__4.obj" scale="1. 1. 1."/>
      </geometry>
    </visual>
    <visual>
      <origin xyz="-0.0000245 -0.1041 -0.0199992" rpy="-1.5707964 -0. 0. "/>
      <geometry>
        <mesh filename="assets_2/link_2_visuals_model2__5_model2__5.obj" scale="1. 1. 1."/>
      </geometry>
    </visual>
  </link>
  <link name="link_3">
    <inertial>
      <origin xyz="-0.121816 -0.054846 -0.000111108" rpy="0 0 0"/>
      <mass value="0.853698"/>
      <inertia ixx="0.000835003" ixy="-0.000536647" ixz="-1.03114e-05" iyy="0.00694973" iyz="-6.38588e-06" izz="0.00696195"/>
    </inertial>
    <visual>
      <origin xyz="0.0000245 0.104101 0.244001 " rpy="-1.5707964 0. 3.1415927"/>
      <geometry>
        <mesh filename="assets_2/link_3_visuals_model2__6_model2__6.obj" scale="1. 1. 1."/>
      </geometry>
    </visual>
    <visual>
      <origin xyz="0.0000245 0.104101 0.244001 " rpy="-1.5707964 0. 3.1415927"/>
      <geometry>
        <mesh filename="assets_2/link_3_visuals_model2__7_model2__7.obj" scale="1. 1. 1."/>
      </geometry>
    </visual>
    <visual>
      <origin xyz="0.0000245 0.104101 0.244001 " rpy="-1.5707964 0. 3.1415927"/>
      <geometry>
        <mesh filename="assets_2/link_3_visuals_model2__8_model2__8.obj" scale="1. 1. 1."/>
      </geometry>
    </visual>
    <visual>
      <origin xyz="0.0000245 0.104101 0.244001 " rpy="-1.5707964 0. 3.1415927"/>
      <geometry>
        <mesh filename="assets_2/link_3_visuals_model2__9_model2__9.obj" scale="1. 1. 1."/>
      </geometry>
    </visual>
  </link>
  <link name="link_4">
    <inertial>
      <origin xyz="-0.0569778 -0.0527104 0.000154878" rpy="0. 0. 0."/>
      <mass value="0.463511"/>
      <inertia ixx="0.000582374" ixy="-0.000250406" ixz="-7.15749e-06" iyy="0.000491129" iyz="-3.22486e-06" izz="0.000744878"/>
    </inertial>
    <visual>
      <origin xyz="0.0000245 0.164101 -0.0010002" rpy="-1.5707964 0. -3.1415927"/>
      <geometry>
        <mesh filename="assets_2/link_4_visuals_model2__10_model2__10.obj" scale="1. 1. 1."/>
      </geometry>
    </visual>
  </link>
  <link name="link_5">
    <inertial>
      <origin xyz="3.64861e-05 0.00025665 0.0353526" rpy="0. 0. 0."/>
      <mass value="0.350962"/>
      <inertia ixx="0.000197798" ixy="-3.20004e-07" ixz="-2.01757e-07" iyy="0.000172615" iyz="-1.10998e-05" izz="0.000152291"/>
    </inertial>
    <visual>
      <origin xyz="0.203601 -0.0749971 0. " rpy="3.14159 1.5707964 0. "/>
      <geometry>
        <mesh filename="assets_2/link_5_visuals_model2__11_model2__11.obj" scale="1. 1. 1."/>
      </geometry>
    </visual>
  </link>
  <link name="link_6">
    <inertial>
      <origin xyz="-0.000217767 7.37059e-05 0.0270545" rpy="0. 0. 0."/>
      <mass value="0.367476"/>
      <inertia ixx="0.000265958" ixy="0" ixz="0" iyy="0.000242686" iyz="0" izz="0.000227409"/>
    </inertial>
    <visual>
      <origin xyz="-0.110597 -0.164101 -0. " rpy="-1.5707963 1.5707963 0. "/>
      <geometry>
        <mesh filename="assets_2/link_6_visuals_model2__12_model2__12.obj" scale="1. 1. 1."/>
      </geometry>
    </visual>
    <visual>
      <origin xyz="-0.110597 -0.164101 -0. " rpy="-1.5707963 1.5707963 0. "/>
      <geometry>
        <mesh filename="assets_2/link_6_visuals_model2__13_model2__13.obj" scale="1. 1. 1."/>
      </geometry>
    </visual>
    <visual>
      <origin xyz="0.05 0.05 0.035 " rpy="-1.5707963 3.1415 0. "/>
      <geometry>
        <mesh filename="assets_2/new_camera_mount.obj" scale="0.001 0.001 0.001"/>
      </geometry>
    </visual>
    <visual>
      <origin xyz="0.0653 0.0843 -0.0005 " rpy="-0.22 1.5707963 -0.92 "/>
      <geometry>
        <mesh filename="assets_2/camera_enclosure.obj" scale="0.001 0.001 0.001"/>
      </geometry>
    </visual>
    <!-- <visual>
      <origin xyz="0. 0. -0." rpy="-1.5707964 0.0000001 -1.5707964"/>
      <geometry>
        <sphere radius="0.005"/>
      </geometry>
    </visual> -->
    <!-- <visual>
      <origin xyz="0.1347 -0. -0. " rpy="-1.5707964 0.0000001 -1.5707964"/>
      <geometry>
        <sphere radius="0.005"/>
      </geometry>
    </visual> -->
  </link>
  <link name="link_left_finger">
    <inertial>
      <origin xyz="-0.0192995 -0.0365902 0.039774 " rpy="0. 0. 0."/>
      <mass value="0.118"/>
      <inertia ixx="0.000159084" ixy="0" ixz="0" iyy="0.000154909" iyz="0" izz="4.63655e-05"/>
    </inertial>
    <visual>
      <origin xyz="0.037 -0.203301 -0.171097" rpy="-1.5707964 -0. -0. "/>
      <geometry>
        <mesh filename="assets_2/link_left_finger_visuals_model2__14_model2__14.obj" scale="1. 1. 1."/>
      </geometry>
    </visual>
    <visual>
      <origin xyz="0.037 -0.203301 -0.171097" rpy="-1.5707964 -0. -0. "/>
      <geometry>
        <mesh filename="assets_2/link_left_finger_visuals_model2__15_model2__15.obj" scale="1. 1. 1."/>
      </geometry>
    </visual>
  </link>
  <link name="link_right_finger">
    <inertial>
      <origin xyz="-0.0192995 0.0365902 -0.039774 " rpy="0. 0. 0."/>
      <mass value="0.118"/>
      <inertia ixx="0.000159084" ixy="0" ixz="0" iyy="0.000154909" iyz="0" izz="4.63655e-05"/>
    </inertial>
    <visual>
      <origin xyz="-0.037 -0.124901 -0.171097" rpy="-1.5707964 -0. -0. "/>
      <geometry>
        <mesh filename="assets_2/link_right_finger_visuals_model2__16_model2__16.obj" scale="1. 1. 1."/>
      </geometry>
    </visual>
    <visual>
      <origin xyz="-0.037 -0.124901 -0.171097" rpy="-1.5707964 -0. -0. "/>
      <geometry>
        <mesh filename="assets_2/link_right_finger_visuals_model2__17_model2__17.obj" scale="1. 1. 1."/>
      </geometry>
    </visual>
  </link>
  <link name="base_link">
    <inertial>
      <origin xyz="-7.22812e-05 2.52572e-05 0.0159932" rpy="0 0 0"/>
      <mass value="0.822546"/>
      <inertia ixx="0.00169415" ixy="2.43507e-07" ixz="-1.31515e-07" iyy="0.00066093" iyz="-9.11171e-07" izz="0.00155626"/>
    </inertial>
    <visual>
      <origin xyz="0. 0. -0.0006" rpy="0. 0. 1.5707963"/>
      <geometry>
        <mesh filename="assets_2/base_link_visuals_model2_model2.obj" scale="1. 1. 1."/>
      </geometry>
    </visual>
  </link>
</robot>
